Workbook

Sheet Claude Log
A1: Turn # | B1: Date | C1: User Request | D1: Action Taken | E1: Details | F1: Outcome
A2: 1 | B2: 46094 | C2: Revisión general del modelo de evaluación financiera solar (6 hojas). | D2: Diagnóstico completo. Identificado error crítico en Payback Simple (C10) y Descontado (C11). | E2: Fórmulas usaban operador @ que bloqueaba MATCH como arreglo. Además, celdas C10, C11 y C29 tenían formato texto (@) que impedía el cálculo. | F2: Error diagnosticado. Presentado al usuario para confirmación.
A3: 2 | B3: 46094 | C3: Usuario confirmó: corregir ambas fórmulas de Payback (Simple y Descontado). | D3: Corregidas fórmulas en C10, C11. Cambiado formato de @ (texto) a 0.0 (numérico). Corregido C29 (tabla de decisión). | E3: Reemplazado @rango>=0 por INDEX(rango>=0,0) en MATCH para forzar evaluación de arreglo. Cambio de numberFormat de '@' a '0.0'. C29 también tenía formato texto — corregido. Fórmula D29 (veredicto) se actualizó automáticamente. | F3: Payback Simple = 3.4 años | Payback Descontado = 4.7 años | Veredicto: ✅ ≤ 5 años — EXCELENTE. Todos los indicadores ahora son consistentes.
A4: 3 | B4: 46094 | C4: Usuario agradeció la corrección realizada. | D4: Ninguna acción adicional requerida. | E4: Correcciones de Payback confirmadas por el usuario. Modelo completo y consistente. | F4: Modelo listo. VPN=$107.7M, TIR=26.1%, B/C=3.87, Payback Simple=3.4 años, Payback Descontado=4.7 años. Todos los indicadores alineados.
A5: 4 | B5: 46094 | C5: Usuario pregunta por qué la TIR con financiamiento es 73.80% y dónde se usa el WACC en el cálculo | D5: Revisé fórmulas de TIR, VPN, WACC y flujo de caja completo para explicar la relación | E5: TIR=IRR(flujo financiero neto) usa solo aporte propio -$37.6M como inversión. WACC=12.042% calculado pero usado solo como referencia, no como tasa de descuento. VPN descuenta con TMAR 12%, no con WACC. | F5: Explicación entregada. Se ofreció agregar flujo del proyecto puro o modificar VPN para usar WACC. Esperando decisión del usuario.
A6: 5 | B6: 46094 | C6: Implementar Enfoque A: usar WACC cuando hay financiamiento y TMAR cuando no, para VPN, flujo descontado e indicadores | D6: Modificadas fórmulas en 4_INDICADORES y 3_FLUJO_CAJA para selección dinámica de tasa según celda SI/NO de 1_ENTRADA!C64 | E6: VPN: NPV(IF(SI→WACC,NO→TMAR),...). Flujo descontado fila 27: refs absolutas $C$64,$C$70,$C$54 con exponentes dinámicos COLUMN()-COLUMN($B$27). Etiquetas dinámicas en B4,B6,B7,D4,D5,D6,D11,D26,D28,A27. Corregido formato texto en C7. | F6: VPN=$167.96M (antes $168.52M con TMAR). TIR=73.80% sin cambio (IRR no usa tasa). WACC=12.042% ahora es tasa de referencia. Payback descontado=1.63 años. Flujo acumulado final coincide con VPN. Todo dinámico: cambiar SI→NO en 1_ENTRADA!C64 switchea automáticamente a TMAR.

Sheet 1_ENTRADA
B1: ☀ EVALUADOR FINANCIERO — PROYECTOS FOTOVOLTAICOS ON-GRID
B2: Texto azul = datos de entrada | Texto negro = fórmulas automáticas | Texto verde = vínculo entre hojas
B3: A. IDENTIFICACIÓN DEL PROYECTO
B4: PARÁMETRO | C4: VALOR | D4: UNIDAD | E4: NOTA / FUENTE
B5: Nombre del proyecto | C5: Proyecto Fotovoltaico On-Grid | D5: -
B6: Cliente | C6: Suegra | D6: -
B7: Ubicación | C7: Riohacha, La Guajira | D7: -
B8: Operador de Red | C8: AIR-E | D8: -
B9: Año de inicio de operación | C9: 2026 | D9: año
B11: B. PARÁMETROS TÉCNICOS DEL SISTEMA SOLAR
B12: PARÁMETRO | C12: VALOR | D12: UNIDAD | E12: NOTA / FUENTE
B13: Potencia pico del panel (Wp) | C13: 610 | D13: Wp | E13: Ficha técnica del fabricante
B14: Número de paneles instalados | C14: 20 | D14: und | E14: Según diseño técnico
B15: Potencia pico DC instalada (kWp) | C15: =(C13*C14)/1000 -> 12.2 | D15: kWp | E15: paneles x Wp / 1000
B16: Potencia total del inversor (kW AC) | C16: 12 | D16: kW | E16: Suma de inversores
B17: Horas de Irradiación Solar Pico (HSP) | C17: 5 | D17: h/día | E17: ATLAS solar / histórico local
B18: Factor de rendimiento del sistema (PR) | C18: 0.9 | D18: adim. | E18: Típico: 0.80 – 0.90
B19: Energía generada por el sistema / mes | C19: ='2_CALC_KWH'!C11 -> 0 | D19: kWh/mes | E19: Calculado en hoja 2
B20: Consumo de la red eléctrica | C20: 3700 | D20: kWh/mes | E20: Promedio factura 12 meses
B21: Cobertura solar del consumo | C21: ='2_CALC_KWH'!C13/C20 -> 0.44513514 | D21: % | E21: Generación / Consumo
B22: Degradación panel — año 1 | C22: 0.025 | D22: %/año | E22: Garantía fabricante ≈ 2.5%
B23: Degradación panel — años 2-25 | C23: 0.0055 | D23: %/año | E23: Garantía fabricante ≈ 0.55%
B25: C. TARIFAS DE ENERGÍA
B26: PARÁMETRO | C26: VALOR | D26: UNIDAD | E26: NOTA / FUENTE
B27: Tarifa de compra de la red — CU ($/kWh) | C27: 891 | D27: $/kWh | E27: Última factura de energía
B28: Precio excedentes a la red ($/kWh) | C28: 436 | D28: $/kWh | E28: Precio de bolsa XM — mercado spot
B29: Crecimiento tarifario anual (%) | C29: 0.067 | D29: %/año | E29: CREG — proyección sector eléctrico
B30: ¿Hay excedentes inyectados a la red? | C30: SI | D30: SI/NO | E30: SI = neteo de excedentes
B32: D. PRESUPUESTO — INVERSIÓN INICIAL (CAPEX sin IVA)
B33: COMPONENTE | C33: VALOR SIN IVA (COP) | D33: IVA | E33: VALOR CON IVA (COP)
B34: Paneles solares | C34: 24400000 | D34: 0 | E34: =C34*(1+D34) -> 24400000
B35: Inversores / Datalogger | C35: 22000000 | D35: 0 | E35: =C35*(1+D35) -> 22000000
B36: Estructura de montaje | C36: 23000000 | D36: 0.19 | E36: =C36*(1+D36) -> 27370000
B37: Cables AC | C37: 3000000 | D37: 0.19 | E37: =C37*(1+D37) -> 3570000
B38: Cables DC y conectores MC4 | C38: 4800000 | D38: 0.19 | E38: =C38*(1+D38) -> 5712000
B39: Tablero de protecciones | C39: 5000000 | D39: 0.19 | E39: =C39*(1+D39) -> 5950000
B40: Canalización AC/DC | C40: 3500000 | D40: 0.19 | E40: =C40*(1+D40) -> 4165000
B41: Medidor bidireccional | C41: 2200000 | D41: 0.19 | E41: =C41*(1+D41) -> 2618000
B42: Mano de obra e ingeniería | C42: 12500000 | D42: 0.19 | E42: =C42*(1+D42) -> 14875000
B43: Administración — AIU | C43: 4000000 | D43: 0 | E43: =C43*(1+D43) -> 4000000
...

Sheet 2_CALC_KWH
B1: 🔆 CÁLCULO DEL SISTEMA SOLAR — GENERACIÓN Y AHORRO EN FACTURA
B2: PARÁMETROS TÉCNICOS (vinculados de hoja 1)
B3: PARÁMETRO | C3: VALOR | D3: UNIDAD
B4: Potencia pico del panel (Wp) | C4: ='1_ENTRADA'!C13 -> 610 | D4: Wp
B5: Número de paneles instalados | C5: ='1_ENTRADA'!C14 -> 20 | D5: und
B6: Potencia pico DC instalada (kWp) | C6: =C4*C5/1000 -> 12.2 | D6: kWp
B7: HSP — horas irradiación solar pico | C7: ='1_ENTRADA'!C17 -> 5 | D7: h/día
B8: Factor de rendimiento PR | C8: ='1_ENTRADA'!C18 -> 0.9 | D8: adim.
B9: Consumo de la red (kWh/mes) | C9: ='1_ENTRADA'!C20 -> 3700 | D9: kWh/mes
B11: GENERACIÓN ENERGÉTICA DEL SISTEMA SOLAR
B12: CONCEPTO | C12: VALOR | D12: UNIDAD
B13: Energía generada / mes (kWh/mes) | C13: =C4*C5*C7*C8*30/1000 -> 1647 | D13: kWh/mes
B14: Energía generada / año (kWh/año) | C14: =C13*12 -> 19764 | D14: kWh/año
B15: Cobertura solar del consumo (%) | C15: =IF(C9=0,0,C13/C9) -> 0.44513514 | D15: %
B16: Autoconsumo estimado (kWh/mes) | C16: =MIN(C13,C9) -> 1647 | D16: kWh/mes
B17: Excedentes a la red (kWh/mes) | C17: =MAX(0,C13-C9) -> 0 | D17: kWh/mes
B19: AHORRO EN FACTURA — AÑO BASE (sin degradación)
B20: CONCEPTO | C20: VALOR | D20: UNIDAD
B21: Tarifa de la red — CU ($/kWh) | C21: ='1_ENTRADA'!C27 -> 891 | D21: $/kWh
B22: Valor factura actual (COP/mes) | C22: ='1_ENTRADA'!C20*C21 -> 3296700 | D22: COP/mes
B23: Ahorro por autoconsumo (COP/mes) | C23: =C16*C21 -> 1467477 | D23: COP/mes
B24: Ingreso por excedentes a la red (COP/mes) | C24: =C17*'1_ENTRADA'!C28 -> 0 | D24: COP/mes
B25: AHORRO TOTAL MENSUAL (COP/mes) | C25: =C23+C24 -> 1467477 | D25: COP/mes
B26: AHORRO TOTAL ANUAL (COP/año) | C26: =C25*12 -> 17609724 | D26: COP/año
B27: Costo por kWp instalado (COP/kWp) | C27: =IF(C6=0,0,'1_ENTRADA'!C47/C6) -> 9049180.3 | D27: COP/kWp

Sheet 3_FLUJO_CAJA
A1: 💰 FLUJO DE CAJA DEL PROYECTO — TÉRMINOS DEFLACTADOS (precios constantes año base)
A2: CONCEPTO | B2: Año 0 | C2: 1 | D2: 2 | E2: 3 | F2: 4 | G2: 5 | H2: 6 | I2: 7 | J2: 8 | K2: 9 | L2: 10 | M2: 11 | N2: 12 | O2: 13 | P2: 14 | Q2: 15 | R2: 16 | S2: 17 | T2: 18 | U2: 19 | V2: 20 | W2: 21 | X2: 22 | Y2: 23 | Z2: 24 | AA2: 25
A3: I. INVERSIÓN
A4: (-) CAPEX (Inversión inicial) | B4: =-'1_ENTRADA'!E47 -> -121230000
A5: (+) Crédito bancario recibido | B5: ='1_ENTRADA'!C66 -> 84861000
A6: FLUJO NETO DE INVERSIÓN | B6: =B4+B5 -> -36369000
A7: II. INGRESOS Y BENEFICIOS
A8: Ahorro en factura — autoconsumo | B8: 0 | C8: ='2_CALC_KWH'!C26*C11 -> 17169481 | D8: ='2_CALC_KWH'!C26*D11 -> 17075049 | E8: ='2_CALC_KWH'!C26*E11 -> 16981136 | F8: ='2_CALC_KWH'!C26*F11 -> 16887740 | G8: ='2_CALC_KWH'!C26*G11 -> 16794857 | H8: ='2_CALC_KWH'!C26*H11 -> 16702485 | I8: ='2_CALC_KWH'!C26*I11 -> 16610622 | J8: ='2_CALC_KWH'!C26*J11 -> 16519263 | K8: ='2_CALC_KWH'!C26*K11 -> 16428407 | L8: ='2_CALC_KWH'!C26*L11 -> 16338051 | M8: ='2_CALC_KWH'!C26*M11 -> 16248192 | N8: ='2_CALC_KWH'!C26*N11 -> 16158827 | O8: ='2_CALC_KWH'!C26*O11 -> 16069953 | P8: ='2_CALC_KWH'!C26*P11 -> 15981569 | Q8: ='2_CALC_KWH'!C26*Q11 -> 15893670 | R8: ='2_CALC_KWH'!C26*R11 -> 15806255 | S8: ='2_CALC_KWH'!C26*S11 -> 15719320 | T8: ='2_CALC_KWH'!C26*T11 -> 15632864 | U8: ='2_CALC_KWH'!C26*U11 -> 15546883 | V8: ='2_CALC_KWH'!C26*V11 -> 15461375 | W8: ='2_CALC_KWH'!C26*W11 -> 15376338 | X8: ='2_CALC_KWH'!C26*X11 -> 15291768 | Y8: ='2_CALC_KWH'!C26*Y11 -> 15207663 | Z8: ='2_CALC_KWH'!C26*Z11 -> 15124021 | AA8: ='2_CALC_KWH'!C26*AA11 -> 15040839
A9: Ingreso por excedentes a la red | B9: 0 | C9: =IF('1_ENTRADA'!C30="SI",'2_CALC_KWH'!C17*12*'1_ENTRADA'!C28*C11,0) -> 0 | D9: =IF('1_ENTRADA'!C30="SI",'2_CALC_KWH'!C17*12*'1_ENTRADA'!C28*D11,0) -> 0 | E9: =IF('1_ENTRADA'!C30="SI",'2_CALC_KWH'!C17*12*'1_ENTRADA'!C28*E11,0) -> 0 | F9: =IF('1_ENTRADA'!C30="SI",'2_CALC_KWH'!C17*12*'1_ENTRADA'!C28*F11,0) -> 0 | G9: =IF('1_ENTRADA'!C30="SI",'2_CALC_KWH'!C17*12*'1_ENTRADA'!C28*G11,0) -> 0 | H9: =IF('1_ENTRADA'!C30="SI",'2_CALC_KWH'!C17*12*'1_ENTRADA'!C28*H11,0) -> 0 | I9: =IF('1_ENTRADA'!C30="SI",'2_CALC_KWH'!C17*12*'1_ENTRADA'!C28*I11,0) -> 0 | J9: =IF('1_ENTRADA'!C30="SI",'2_CALC_KWH'!C17*12*'1_ENTRADA'!C28*J11,0) -> 0 | K9: =IF('1_ENTRADA'!C30="SI",'2_CALC_KWH'!C17*12*'1_ENTRADA'!C28*K11,0) -> 0 | L9: =IF('1_ENTRADA'!C30="SI",'2_CALC_KWH'!C17*12*'1_ENTRADA'!C28*L11,0) -> 0 | M9: =IF('1_ENTRADA'!C30="SI",'2_CALC_KWH'!C17*12*'1_ENTRADA'!C28*M11,0) -> 0 | N9: =IF('1_ENTRADA'!C30="SI",'2_CALC_KWH'!C17*12*'1_ENTRADA'!C28*N11,0) -> 0 | O9: =IF('1_ENTRADA'!C30="SI",'2_CALC_KWH'!C17*12*'1_ENTRADA'!C28*O11,0) -> 0 | P9: =IF('1_ENTRADA'!C30="SI",'2_CALC_KWH'!C17*12*'1_ENTRADA'!C28*P11,0) -> 0 | Q9: =IF('1_ENTRADA'!C30="SI",'2_CALC_KWH'!C17*12*'1_ENTRADA'!C28*Q11,0) -> 0 | R9: =IF('1_ENTRADA'!C30="SI",'2_CALC_KWH'!C17*12*'1_ENTRADA'!C28*R11,0) -> 0 | S9: =IF('1_ENTRADA'!C30="SI",'2_CALC_KWH'!C17*12*'1_ENTRADA'!C28*S11,0) -> 0 | T9: =IF('1_ENTRADA'!C30="SI",'2_CALC_KWH'!C17*12*'1_ENTRADA'!C28*T11,0) -> 0 | U9: =IF('1_ENTRADA'!C30="SI",'2_CALC_KWH'!C17*12*'1_ENTRADA'!C28*U11,0) -> 0 | V9: =IF('1_ENTRADA'!C30="SI",'2_CALC_KWH'!C17*12*'1_ENTRADA'!C28*V11,0) -> 0 | W9: =IF('1_ENTRADA'!C30="SI",'2_CALC_KWH'!C17*12*'1_ENTRADA'!C28*W11,0) -> 0 | X9: =IF('1_ENTRADA'!C30="SI",'2_CALC_KWH'!C17*12*'1_ENTRADA'!C28*X11,0) -> 0 | Y9: =IF('1_ENTRADA'!C30="SI",'2_CALC_KWH'!C17*12*'1_ENTRADA'!C28*Y11,0) -> 0 | Z9: =IF('1_ENTRADA'!C30="SI",'2_CALC_KWH'!C17*12*'1_ENTRADA'!C28*Z11,0) -> 0 | AA9: =IF('1_ENTRADA'!C30="SI",'2_CALC_KWH'!C17*12*'1_ENTRADA'!C28*AA11,0) -> 0
A10: Beneficio tributario Ley 1715 | B10: 0 | C10: =IF(C2<='1_ENTRADA'!$C58,'1_ENTRADA'!$E48/'1_ENTRADA'!$C58,0) -> 12123000 | D10: =IF(D2<='1_ENTRADA'!$C58,'1_ENTRADA'!$E48/'1_ENTRADA'!$C58,0) -> 12123000 | E10: =IF(E2<='1_ENTRADA'!$C58,'1_ENTRADA'!$E48/'1_ENTRADA'!$C58,0) -> 12123000 | F10: =IF(F2<='1_ENTRADA'!$C58,'1_ENTRADA'!$E48/'1_ENTRADA'!$C58,0) -> 12123000 | G10: =IF(G2<='1_ENTRADA'!$C58,'1_ENTRADA'!$E48/'1_ENTRADA'!$C58,0) -> 12123000 | H10: =IF(H2<='1_ENTRADA'!$C58,'1_ENTRADA'!$E48/'1_ENTRADA'!$C58,0) -> 0 | I10: =IF(I2<='1_ENTRADA'!$C58,'1_ENTRADA'!$E48/'1_ENTRADA'!$C58,0) -> 0 | J10: =IF(J2<='1_ENTRADA'!$C58,'1_ENTRADA'!$E48/'1_ENTRADA'!$C58,0) -> 0 | ... AA10: =IF(AA2<='1_ENTRADA'!$C58,'1_ENTRADA'!$E48/'1_ENTRADA'!$C58,0) -> 0
A11: Factor de degradación del panel | B11: 0 | C11: =(1-'1_ENTRADA'!C22) -> 0.975 | D11: =C11*(1-'1_ENTRADA'!C23) -> 0.9696375 | E11: =D11*(1-'1_ENTRADA'!C23) -> 0.96430449 | F11: =E11*(1-'1_ENTRADA'!C23) -> 0.95900082 | G11: =F11*(1-'1_ENTRADA'!C23) -> 0.95372631 | H11: =G11*(1-'1_ENTRADA'!C23) -> 0.94848082 | I11: =H11*(1-'1_ENTRADA'!C23) -> 0.94326418 | J11: =I11*(1-'1_ENTRADA'!C23) -> 0.93807622 | K11: =J11*(1-'1_ENTRADA'!C23) -> 0.9329168 | L11: =K11*(1-'1_ENTRADA'!C23) -> 0.92778576 | M11: =L11*(1-'1_ENTRADA'!C23) -> 0.92268294 | N11: =M11*(1-'1_ENTRADA'!C23) -> 0.91760818 | O11: =N11*(1-'1_ENTRADA'!C23) -> 0.91256134 | P11: =O11*(1-'1_ENTRADA'!C23) -> 0.90754225 | Q11: =P11*(1-'1_ENTRADA'!C23) -> 0.90255077 | R11: =Q11*(1-'1_ENTRADA'!C23) -> 0.89758674 | S11: =R11*(1-'1_ENTRADA'!C23) -> 0.89265001 | T11: =S11*(1-'1_ENTRADA'!C23) -> 0.88774044 | U11: =T11*(1-'1_ENTRADA'!C23) -> 0.88285786 | V11: =U11*(1-'1_ENTRADA'!C23) -> 0.87800215 | W11: =V11*(1-'1_ENTRADA'!C23) -> 0.87317313 | X11: =W11*(1-'1_ENTRADA'!C23) -> 0.86837068 | Y11: =X11*(1-'1_ENTRADA'!C23) -> 0.86359464 | Z11: =Y11*(1-'1_ENTRADA'!C23) -> 0.85884487 | AA11: =Z11*(1-'1_ENTRADA'!C23) -> 0.85412123
A12: TOTAL INGRESOS | B12: 0 | C12: =C8+C9+C10 -> 29292481 | D12: =D8+D9+D10 -> 29198049 | E12: =E8+E9+E10 -> 29104136 | F12: =F8+F9+F10 -> 29010740 | G12: =G8+G9+G10 -> 28917857 | H12: =H8+H9+H10 -> 16702485 | I12: =I8+I9+I10 -> 16610622 | J12: =J8+J9+J10 -> 16519263 | ... AA12: =AA8+AA9+AA10 -> 15040839
A13: III. COSTOS OPERATIVOS (OPEX)
A14: AOM — Operación y mantenimiento | B14: 0 | C14: ='1_ENTRADA'!$E47*'1_ENTRADA'!$C57 -> 3636900 | D14: ='1_ENTRADA'!$E47*'1_ENTRADA'!$C57 -> 3636900 | E14: ='1_ENTRADA'!$E47*'1_ENTRADA'!$C57 -> 3636900 | F14: ='1_ENTRADA'!$E47*'1_ENTRADA'!$C57 -> 3636900 | G14: ='1_ENTRADA'!$E47*'1_ENTRADA'!$C57 -> 3636900 | H14: ='1_ENTRADA'!$E47*'1_ENTRADA'!$C57 -> 3636900 | I14: ='1_ENTRADA'!$E47*'1_ENTRADA'!$C57 -> 3636900 | J14: ='1_ENTRADA'!$E47*'1_ENTRADA'!$C57 -> 3636900 | ... AA14: ='1_ENTRADA'!$E47*'1_ENTRADA'!$C57 -> 3636900
A15: Depreciación de activos | B15: 0 | C15: =IF(C2<='1_ENTRADA'!$C58,'1_ENTRADA'!$E47*'1_ENTRADA'!$C59/'1_ENTRADA'!$C58,0) -> 9455940 | D15: =IF(D2<='1_ENTRADA'!$C58,'1_ENTRADA'!$E47*'1_ENTRADA'!$C59/'1_ENTRADA'!$C58,0) -> 9455940 | E15: =IF(E2<='1_ENTRADA'!$C58,'1_ENTRADA'!$E47*'1_ENTRADA'!$C59/'1_ENTRADA'!$C58,0) -> 9455940 | F15: =IF(F2<='1_ENTRADA'!$C58,'1_ENTRADA'!$E47*'1_ENTRADA'!$C59/'1_ENTRADA'!$C58,0) -> 9455940 | G15: =IF(G2<='1_ENTRADA'!$C58,'1_ENTRADA'!$E47*'1_ENTRADA'!$C59/'1_ENTRADA'!$C58,0) -> 9455940 | H15: =IF(H2<='1_ENTRADA'!$C58,'1_ENTRADA'!$E47*'1_ENTRADA'!$C59/'1_ENTRADA'!$C58,0) -> 0 | I15: =IF(I2<='1_ENTRADA'!$C58,'1_ENTRADA'!$E47*'1_ENTRADA'!$C59/'1_ENTRADA'!$C58,0) -> 0 | J15: =IF(J2<='1_ENTRADA'!$C58,'1_ENTRADA'!$E47*'1_ENTRADA'!$C59/'1_ENTRADA'!$C58,0) -> 0 | ... AA15: =IF(AA2<='1_ENTRADA'!$C58,'1_ENTRADA'!$E47*'1_ENTRADA'!$C59/'1_ENTRADA'!$C58,0) -> 0
A16: Intereses del crédito bancario | B16: 0 | C16: =IF(AND('1_ENTRADA'!C64="SI",1<='1_ENTRADA'!C67),-IPMT('1_ENTRADA'!C68,1,'1_ENTRADA'!C67,'1_ENTRADA'!C66),0) -> 15274980 | D16: =IF(AND('1_ENTRADA'!C64="SI",2<='1_ENTRADA'!C67),-IPMT('1_ENTRADA'!C68,2,'1_ENTRADA'!C67,'1_ENTRADA'!C66),0) -> 13139876 | E16: =IF(AND('1_ENTRADA'!C64="SI",3<='1_ENTRADA'!C67),-IPMT('1_ENTRADA'!C68,3,'1_ENTRADA'!C67,'1_ENTRADA'!C66),0) -> 10620454 | F16: =IF(AND('1_ENTRADA'!C64="SI",4<='1_ENTRADA'!C67),-IPMT('1_ENTRADA'!C68,4,'1_ENTRADA'!C67,'1_ENTRADA'!C66),0) -> 7647535.4 | G16: =IF(AND('1_ENTRADA'!C64="SI",5<='1_ENTRADA'!C67),-IPMT('1_ENTRADA'!C68,5,'1_ENTRADA'!C67,'1_ENTRADA'!C66),0) -> 4139491.6 | H16: =IF(AND('1_ENTRADA'!C64="SI",6<='1_ENTRADA'!C67),-IPMT('1_ENTRADA'!C68,6,'1_ENTRADA'!C67,'1_ENTRADA'!C66),0) -> 0 | I16: =IF(AND('1_ENTRADA'!C64="SI",7<='1_ENTRADA'!C67),-IPMT('1_ENTRADA'!C68,7,'1_ENTRADA'!C67,'1_ENTRADA'!C66),0) -> 0 | J16: =IF(AND('1_ENTRADA'!C64="SI",8<='1_ENTRADA'!C67),-IPMT('1_ENTRADA'!C68,8,'1_ENTRADA'!C67,'1_ENTRADA'!C66),0) -> 0 | K16: =IF(AND('1_ENTRADA'!C64="SI",9<='1_ENTRADA'!C67),-IPMT('1_ENTRADA'!C68,9,'1_ENTRADA'!C67,'1_ENTRADA'!C66),0) -> 0 | L16: =IF(AND('1_ENTRADA'!C64="SI",10<='1_ENTRADA'!C67),-IPMT('1_ENTRADA'!C68,10,'1_ENTRADA'!C67,'1_ENTRADA'!C66),0) -> 0 | M16: =IF(AND('1_ENTRADA'!C64="SI",11<='1_ENTRADA'!C67),-IPMT('1_ENTRADA'!C68,11,'1_ENTRADA'!C67,'1_ENTRADA'!C66),0) -> 0 | N16: =IF(AND('1_ENTRADA'!C64="SI",12<='1_ENTRADA'!C67),-IPMT('1_ENTRADA'!C68,12,'1_ENTRADA'!C67,'1_ENTRADA'!C66),0) -> 0 | O16: =IF(AND('1_ENTRADA'!C64="SI",13<='1_ENTRADA'!C67),-IPMT('1_ENTRADA'!C68,13,'1_ENTRADA'!C67,'1_ENTRADA'!C66),0) -> 0 | P16: =IF(AND('1_ENTRADA'!C64="SI",14<='1_ENTRADA'!C67),-IPMT('1_ENTRADA'!C68,14,'1_ENTRADA'!C67,'1_ENTRADA'!C66),0) -> 0 | Q16: =IF(AND('1_ENTRADA'!C64="SI",15<='1_ENTRADA'!C67),-IPMT('1_ENTRADA'!C68,15,'1_ENTRADA'!C67,'1_ENTRADA'!C66),0) -> 0 | R16: =IF(AND('1_ENTRADA'!C64="SI",16<='1_ENTRADA'!C67),-IPMT('1_ENTRADA'!C68,16,'1_ENTRADA'!C67,'1_ENTRADA'!C66),0) -> 0 | S16: =IF(AND('1_ENTRADA'!C64="SI",17<='1_ENTRADA'!C67),-IPMT('1_ENTRADA'!C68,17,'1_ENTRADA'!C67,'1_ENTRADA'!C66),0) -> 0 | T16: =IF(AND('1_ENTRADA'!C64="SI",18<='1_ENTRADA'!C67),-IPMT('1_ENTRADA'!C68,18,'1_ENTRADA'!C67,'1_ENTRADA'!C66),0) -> 0 | U16: =IF(AND('1_ENTRADA'!C64="SI",19<='1_ENTRADA'!C67),-IPMT('1_ENTRADA'!C68,19,'1_ENTRADA'!C67,'1_ENTRADA'!C66),0) -> 0 | V16: =IF(AND('1_ENTRADA'!C64="SI",20<='1_ENTRADA'!C67),-IPMT('1_ENTRADA'!C68,20,'1_ENTRADA'!C67,'1_ENTRADA'!C66),0) -> 0 | W16: =IF(AND('1_ENTRADA'!C64="SI",21<='1_ENTRADA'!C67),-IPMT('1_ENTRADA'!C68,21,'1_ENTRADA'!C67,'1_ENTRADA'!C66),0) -> 0 | X16: =IF(AND('1_ENTRADA'!C64="SI",22<='1_ENTRADA'!C67),-IPMT('1_ENTRADA'!C68,22,'1_ENTRADA'!C67,'1_ENTRADA'!C66),0) -> 0 | Y16: =IF(AND('1_ENTRADA'!C64="SI",23<='1_ENTRADA'!C67),-IPMT('1_ENTRADA'!C68,23,'1_ENTRADA'!C67,'1_ENTRADA'!C66),0) -> 0 | Z16: =IF(AND('1_ENTRADA'!C64="SI",24<='1_ENTRADA'!C67),-IPMT('1_ENTRADA'!C68,24,'1_ENTRADA'!C67,'1_ENTRADA'!C66),0) -> 0 | AA16: =IF(AND('1_ENTRADA'!C64="SI",25<='1_ENTRADA'!C67),-IPMT('1_ENTRADA'!C68,25,'1_ENTRADA'!C67,'1_ENTRADA'!C66),0) -> 0
A17: TOTAL COSTOS | B17: 0 | C17: =C14+C15+C16 -> 28367820 | D17: =D14+D15+D16 -> 26232716 | E17: =E14+E15+E16 -> 23713294 | F17: =F14+F15+F16 -> 20740375 | G17: =G14+G15+G16 -> 17232332 | H17: =H14+H15+H16 -> 3636900 | I17: =I14+I15+I16 -> 3636900 | J17: =J14+J15+J16 -> 3636900 | ... AA17: =AA14+AA15+AA16 -> 3636900
A18: IV. FLUJO NETO
A19: Utilidad antes de impuestos | B19: 0 | C19: =C12-C17 -> 924660.9 | D19: =D12-D17 -> 2965332.5 | E19: =E12-E17 -> 5390842.1 | F19: =F12-F17 -> 8270364.3 | G19: =G12-G17 -> 11685526 | H19: =H12-H17 -> 13065585 | I19: =I12-I17 -> 12973722 | J19: =J12-J17 -> 12882363 | ... AA19: =AA12-AA17 -> 11403939
A20: (-) Impuesto de renta | B20: 0 | C20: =IF(C19>0,C19*'1_ENTRADA'!C60,0) -> 305138.1 | D20: =IF(D19>0,D19*'1_ENTRADA'!C60,0) -> 978559.72 | E20: =IF(E19>0,E19*'1_ENTRADA'!C60,0) -> 1778977.9 | F20: =IF(F19>0,F19*'1_ENTRADA'!C60,0) -> 2729220.2 | G20: =IF(G19>0,G19*'1_ENTRADA'!C60,0) -> 3856223.4 | H20: =IF(H19>0,H19*'1_ENTRADA'!C60,0) -> 4311643.2 | I20: =IF(I19>0,I19*'1_ENTRADA'!C60,0) -> 4281328.2 | J20: =IF(J19>0,J19*'1_ENTRADA'!C60,0) -> 4251179.9 | K20: =IF(K19>0,K19*'1_ENTRADA'!C60,0) -> 4221197.4 | L20: =IF(L19>0,L19*'1_ENTRADA'!C60,0) -> 4191379.9 | M20: =IF(M19>0,M19*'1_ENTRADA'!C60,0) -> 4161726.3 | N20: =IF(N19>0,N19*'1_ENTRADA'!C60,0) -> 4132235.9 | O20: =IF(O19>0,O19*'1_ENTRADA'!C60,0) -> 4102907.6 | P20: =IF(P19>0,P19*'1_ENTRADA'!C60,0) -> 4073740.6 | Q20: =IF(Q19>0,Q19*'1_ENTRADA'!C60,0) -> 4044734.1 | R20: =IF(R19>0,R19*'1_ENTRADA'!C60,0) -> 4015887.1 | S20: =IF(S19>0,S19*'1_ENTRADA'!C60,0) -> 3987198.7 | T20: =IF(T19>0,T19*'1_ENTRADA'!C60,0) -> 3958668.1 | U20: =IF(U19>0,U19*'1_ENTRADA'!C60,0) -> 3930294.5 | V20: =IF(V19>0,V19*'1_ENTRADA'!C60,0) -> 3902076.9 | W20: =IF(W19>0,W19*'1_ENTRADA'!C60,0) -> 3874014.5 | X20: =IF(X19>0,X19*'1_ENTRADA'!C60,0) -> 3846106.5 | Y20: =IF(Y19>0,Y19*'1_ENTRADA'!C60,0) -> 3818351.9 | Z20: =IF(Z19>0,Z19*'1_ENTRADA'!C60,0) -> 3790750 | AA20: =IF(AA19>0,AA19*'1_ENTRADA'!C60,0) -> 3763299.9
A21: Utilidad neta | B21: 0 | C21: =C19-C20 -> 619522.8 | D21: =D19-D20 -> 1986772.8 | E21: =E19-E20 -> 3611864.2 | F21: =F19-F20 -> 5541144.1 | G21: =G19-G20 -> 7829302.1 | H21: =H19-H20 -> 8753942.3 | I21: =I19-I20 -> 8692393.6 | J21: =J19-J20 -> 8631183.5 | ... AA21: =AA19-AA20 -> 7640639.2
A22: (+) Depreciación (no es caja) | B22: 0 | C22: =C15 -> 9455940 | D22: =D15 -> 9455940 | E22: =E15 -> 9455940 | F22: =F15 -> 9455940 | G22: =G15 -> 9455940 | H22: =H15 -> 0 | I22: =I15 -> 0 | J22: =J15 -> 0 | ... AA22: =AA15 -> 0
A23: FLUJO OPERACIONAL (caja) | B23: 0 | C23: =C21+C22 -> 10075463 | D23: =D21+D22 -> 11442713 | E23: =E21+E22 -> 13067804 | F23: =F21+F22 -> 14997084 | G23: =G21+G22 -> 17285242 | H23: =H21+H22 -> 8753942.3 | I23: =I21+I22 -> 8692393.6 | J23: =J21+J22 -> 8631183.5 | ... AA23: =AA21+AA22 -> 7640639.2
A24: FLUJO FINANCIERO NETO | B24: =B6+B23 -> -36369000 | C24: =C6+C23 -> 10075463 | D24: =D6+D23 -> 11442713 | E24: =E6+E23 -> 13067804 | F24: =F6+F23 -> 14997084 | G24: =G6+G23 -> 17285242 | H24: =H6+H23 -> 8753942.3 | I24: =I6+I23 -> 8692393.6 | ... AA24: =AA6+AA23 -> 7640639.2
A25: FLUJO FINANCIERO ACUMULADO | B25: =B24 -> -36369000 | C25: =B25+C24 -> -26293537 | D25: =C25+D24 -> -14850824 | E25: =D25+E24 -> -1783020.2 | F25: =E25+F24 -> 13214064 | G25: =F25+G24 -> 30499306 | H25: =G25+H24 -> 39253248 | I25: =H25+I24 -> 47945642 | J25: =I25+J24 -> 56576825 | ... AA25: =Z25+AA24 -> 1.9426095e+08
A26: Factor deflactor (1+IPC)^n — solo referencia | B26: 1 | C26: =(1+'1_ENTRADA'!C55)^1 -> 1.0928 | D26: =(1+'1_ENTRADA'!C55)^2 -> 1.1942118 | E26: =(1+'1_ENTRADA'!C55)^3 -> 1.3050347 | F26: =(1+'1_ENTRADA'!C55)^4 -> 1.4261419 | G26: =(1+'1_ENTRADA'!C55)^5 -> 1.5584879 | H26: =(1+'1_ENTRADA'!C55)^6 -> 1.7031156 | I26: =(1+'1_ENTRADA'!C55)^7 -> 1.8611647 | J26: =(1+'1_ENTRADA'!C55)^8 -> 2.0338808 | K26: =(1+'1_ENTRADA'!C55)^9 -> 2.2226249 | L26: =(1+'1_ENTRADA'!C55)^10 -> 2.4288845 | M26: =(1+'1_ENTRADA'!C55)^11 -> 2.654285 | N26: =(1+'1_ENTRADA'!C55)^12 -> 2.9006026 | O26: =(1+'1_ENTRADA'!C55)^13 -> 3.1697786 | P26: =(1+'1_ENTRADA'!C55)^14 -> 3.463934 | Q26: =(1+'1_ENTRADA'!C55)^15 -> 3.7853871 | R26: =(1+'1_ENTRADA'!C55)^16 -> 4.136671 | S26: =(1+'1_ENTRADA'!C55)^17 -> 4.5205541 | T26: =(1+'1_ENTRADA'!C55)^18 -> 4.9400615 | U26: =(1+'1_ENTRADA'!C55)^19 -> 5.3984992 | V26: =(1+'1_ENTRADA'!C55)^20 -> 5.8994799 | W26: =(1+'1_ENTRADA'!C55)^21 -> 6.4469516 | X26: =(1+'1_ENTRADA'!C55)^22 -> 7.0452288 | Y26: =(1+'1_ENTRADA'!C55)^23 -> 7.699026 | Z26: =(1+'1_ENTRADA'!C55)^24 -> 8.4134956 | AA26: =(1+'1_ENTRADA'!C55)^25 -> 9.194268
A27: =IF('1_ENTRADA'!C64="SI","FLUJO DESCONTADO con WACC — (1+WACC)^n","FLUJO DESCONTADO con TMAR real — (1+TMAR)^n") -> FLUJO DESCONTADO con WACC — (1+WACC)^n | B27: =B24 -> -36369000 | C27: =C24/(1+IF('1_ENTRADA'!$C$64="SI",'1_ENTRADA'!$C$70,'1_ENTRADA'!$C$54))^(COLUMN()-COLUMN($B$27)) -> 8992576.7 | D27: =D24/(1+IF('1_ENTRADA'!$C$64="SI",'1_ENTRADA'!$C$70,'1_ENTRADA'!$C$54))^(COLUMN()-COLUMN($B$27)) -> 9115222.9 | E27: =E24/(1+IF('1_ENTRADA'!$C$64="SI",'1_ENTRADA'!$C$70,'1_ENTRADA'!$C$54))^(COLUMN()-COLUMN($B$27)) -> 9290948.7 | F27: =F24/(1+IF('1_ENTRADA'!$C$64="SI",'1_ENTRADA'!$C$70,'1_ENTRADA'!$C$54))^(COLUMN()-COLUMN($B$27)) -> 9516635.1 | G27: =G24/(1+IF('1_ENTRADA'!$C$64="SI",'1_ENTRADA'!$C$70,'1_ENTRADA'!$C$54))^(COLUMN()-COLUMN($B$27)) -> 9789741 | H27: =H24/(1+IF('1_ENTRADA'!$C$64="SI",'1_ENTRADA'!$C$70,'1_ENTRADA'!$C$54))^(COLUMN()-COLUMN($B$27)) -> 4425053.9 | I27: =I24/(1+IF('1_ENTRADA'!$C$64="SI",'1_ENTRADA'!$C$70,'1_ENTRADA'!$C$54))^(COLUMN()-COLUMN($B$27)) -> 3921691.4 | J27: =J24/(1+IF('1_ENTRADA'!$C$64="SI",'1_ENTRADA'!$C$70,'1_ENTRADA'!$C$54))^(COLUMN()-COLUMN($B$27)) -> 3475549.9 | ... AA27: =AA24/(1+IF('1_ENTRADA'!$C$64="SI",'1_ENTRADA'!$C$70,'1_ENTRADA'!$C$54))^(COLUMN()-COLUMN($B$27)) -> 445254.56
A28: FLUJO DESCONTADO ACUMULADO | B28: =B27 -> -36369000 | C28: =B28+C27 -> -27376423 | D28: =C28+D27 -> -18261200 | E28: =D28+E27 -> -8970251.7 | F28: =E28+F27 -> 546383.36 | G28: =F28+G27 -> 10336124 | H28: =G28+H27 -> 14761178 | I28: =H28+I27 -> 18682870 | J28: =I28+J27 -> 22158420 | ... AA28: =Z28+AA27 -> 45750253

Sheet 4_INDICADORES
B1: 📊 INDICADORES FINANCIEROS — RESULTADO DE LA EVALUACIÓN
B2: INDICADORES PRINCIPALES
B3: INDICADOR | C3: VALOR | D3: INTERPRETACIÓN
B4: =IF('1_ENTRADA'!C64="SI","VPN — Valor Presente Neto (COP) — precios constantes, WACC","VPN — Valor Presente Neto (COP) — precios constantes, TMAR real") -> VPN — Valor Presente Neto (COP) — precios constantes, WACC | C4: =NPV(IF('1_ENTRADA'!C64="SI",'1_ENTRADA'!C70,'1_ENTRADA'!C54),'3_FLUJO_CAJA'!C24:AA24)+'3_FLUJO_CAJA'!B24 -> 45750253 | D4: =IF('1_ENTRADA'!C64="SI","VPN > 0 → proyecto crea valor | Descontado a WACC (con financiamiento)","VPN > 0 → proyecto crea valor | Descontado a TMAR (sin financiamiento)") -> VPN > 0 → proyecto crea valor | Descontado a WACC (con financiamiento)
B5: TIR — Tasa Interna de Retorno (%) | C5: =IFERROR(IRR('3_FLUJO_CAJA'!B24:AA24),"No converge") -> 0.31459049 | D5: =IF('1_ENTRADA'!C64="SI","TIR > WACC → proyecto rentable","TIR > TMAR → proyecto rentable") -> TIR > WACC → proyecto rentable
B6: =IF('1_ENTRADA'!C64="SI","WACC — Costo promedio ponderado de capital (%)","TMAR — Tasa mínima atractiva de retorno (%)") -> WACC — Costo promedio ponderado de capital (%) | C6: =IF('1_ENTRADA'!C64="SI",'1_ENTRADA'!C70,'1_ENTRADA'!C54) -> 0.12042 | D6: =IF('1_ENTRADA'!C64="SI","Costo mixto ponderado de deuda y equity","Costo de oportunidad del inversionista") -> Costo mixto ponderado de deuda y equity
B7: =IF('1_ENTRADA'!C64="SI","¿TIR > WACC? — Viabilidad","¿TIR > TMAR? — Viabilidad") -> ¿TIR > WACC? — Viabilidad | C7: =IF(ISNUMBER(C5),IF(C5>C6,IF('1_ENTRADA'!C64="SI","✅ ACEPTAR — TIR supera el WACC","✅ ACEPTAR — TIR supera la TMAR"),IF('1_ENTRADA'!C64="SI","❌ RECHAZAR — TIR < WACC","❌ RECHAZAR — TIR < TMAR")),"Revisar flujos") -> ✅ ACEPTAR — TIR supera el WACC | D7: Criterio de decisión principal
B8: Relación Beneficio / Costo (B/C) | C8: =IFERROR((SUM('3_FLUJO_CAJA'!C12:AA12)+'3_FLUJO_CAJA'!B12)/(ABS('3_FLUJO_CAJA'!B4)+SUM('3_FLUJO_CAJA'!C17:AA17)+'3_FLUJO_CAJA'!B17),"Error") -> 1.4912969 | D8: B/C > 1 → viable | B/C < 1 → no viable
B9: ROI — Retorno sobre la Inversión (%) | C9: =IFERROR((SUM('3_FLUJO_CAJA'!C24:AA24)+'3_FLUJO_CAJA'!B24-'1_ENTRADA'!C47)/'1_ENTRADA'!C47,0) -> 0.75961007 | D9: Retorno total neto sobre el CAPEX invertido
B10: Payback Simple — años de recuperación | C10: {=IFERROR(MATCH(TRUE(),INDEX('3_FLUJO_CAJA'!C25:AA25>=0,0),0)-1+ABS(INDEX('3_FLUJO_CAJA'!B25:Z25,MATCH(TRUE(),INDEX('3_FLUJO_CAJA'!C25:AA25>=0,0),0)))/INDEX('3_FLUJO_CAJA'!C24:AA24,MATCH(TRUE(),INDEX('3_FLUJO_CAJA'!C25:AA25>=0,0),0)),">25 años")} -> 3.1188911 | D10: Años (con fracción) hasta recuperar la inversión — flujo acumulado
B11: Payback Descontado — años de recuperación | C11: {=IFERROR(MATCH(TRUE(),INDEX('3_FLUJO_CAJA'!C28:AA28>=0,0),0)-1+ABS(INDEX('3_FLUJO_CAJA'!B28:Z28,MATCH(TRUE(),INDEX('3_FLUJO_CAJA'!C28:AA28>=0,0),0)))/INDEX('3_FLUJO_CAJA'!C27:AA27,MATCH(TRUE(),INDEX('3_FLUJO_CAJA'!C28:AA28>=0,0),0)),">25 años")} -> 3.9425865 | D11: =IF('1_ENTRADA'!C64="SI","Años (con fracción) hasta recuperar inversión en términos descontados — WACC","Años (con fracción) hasta recuperar inversión en términos descontados — TMAR") -> Años (con fracción) hasta recuperar inversión en términos descontados — WACC
B12: WACC — Costo promedio de capital (%) | C12: ='1_ENTRADA'!C70 -> 0.12042 | D12: Costo mixto ponderado de deuda y equity
B13: Inversión total bruta — CAPEX (COP) | C13: ='1_ENTRADA'!E47 -> 121230000
B14: Beneficio tributario Ley 1715 (COP) | C14: ='1_ENTRADA'!E48 -> 60615000 | D14: Ahorro en impuesto de renta — 5 años
B15: Inversión neta efectiva (COP) | C15: ='1_ENTRADA'!E49 -> 60615000 | D15: CAPEX − beneficio tributario
B16: Ahorro mensual en factura — año base (COP) | C16: ='2_CALC_KWH'!C25 -> 1467477 | D16: Sin degradación ni ajuste tarifario
B17: Ahorro anual en factura — año base (COP) | C17: ='2_CALC_KWH'!C26 -> 17609724
B18: Costo por kWp instalado (COP/kWp) | C18: ='2_CALC_KWH'!C27 -> 9049180.3 | D18: Referencia mercado: $3.5M – $5.5M/kWp
B19: Energía generada / mes — año base (kWh) | C19: ='2_CALC_KWH'!C13 -> 1647
B20: Cobertura solar del consumo (%) | C20: ='2_CALC_KWH'!C15 -> 0.44513514
B23: TABLA DE DECISIÓN
B24: INDICADOR | C24: VALOR CALCULADO | D24: CRITERIO Y VEREDICTO
B25: VPN | C25: =C4 -> 45750253 | D25: =IF(ISNUMBER(C4),IF(C4>0,"✅ VPN > 0 — ACEPTAR","❌ VPN < 0 — RECHAZAR"),"Revisar") -> ✅ VPN > 0 — ACEPTAR
B26: TIR | C26: =C5 -> 0.31459049 | D26: =IF(ISNUMBER(C5),IF(C5>C6,IF('1_ENTRADA'!C64="SI","✅ TIR > WACC — ACEPTAR","✅ TIR > TMAR — ACEPTAR"),IF('1_ENTRADA'!C64="SI","❌ TIR < WACC — RECHAZAR","❌ TIR < TMAR — RECHAZAR")),"Revisar") -> ✅ TIR > WACC — ACEPTAR
B27: B/C | C27: =C8 -> 1.4912969 | D27: =IF(ISNUMBER(C8),IF(C8>=1,"✅ B/C ≥ 1 — ACEPTAR","❌ B/C < 1 — RECHAZAR"),"Revisar") -> ✅ B/C ≥ 1 — ACEPTAR
B28: ROI | C28: =C9 -> 0.75961007 | D28: =IF(ISNUMBER(C9),IF(C9>C6,IF('1_ENTRADA'!C64="SI","✅ ROI > WACC — ACEPTAR","✅ ROI > TMAR — ACEPTAR"),IF('1_ENTRADA'!C64="SI","❌ ROI < WACC — RECHAZAR","❌ ROI < TMAR — RECHAZAR")),"Revisar") -> ✅ ROI > WACC — ACEPTAR
B29: Payback | C29: =C10 -> 3.1188911 | D29: =IF(ISNUMBER(C10),IF(C10<=5,"✅ ≤ 5 años — EXCELENTE","⚠️ > 5 años — REVISAR"),"Ver flujo") -> ✅ ≤ 5 años — EXCELENTE

Sheet 5_AMORTIZACION
B1: 🏦 TABLA DE AMORTIZACIÓN DEL CRÉDITO BANCARIO
B2: RESUMEN DEL CRÉDITO
B3: PARÁMETRO | C3: VALOR
B4: Valor del crédito (COP) | C4: ='1_ENTRADA'!C66 -> 84861000
B5: Tasa efectiva anual — TEA (%) | C5: ='1_ENTRADA'!C68 -> 0.18
B6: Plazo (años) | C6: ='1_ENTRADA'!C67 -> 5
B7: Cuota anual uniforme (COP) | C7: =IF(C4=0,0,-PMT(C5,C6,C4)) -> 27136667
B8: Cuota mensual equivalente | C8: =IF(C7=0,0,C7/12) -> 2261389
B10: AÑO | C10: SALDO INICIAL (COP) | D10: CUOTA ANUAL (COP) | E10: INTERESES (COP) | F10: AMORTIZACIÓN (COP) | G10: SALDO FINAL (COP)
B11: 0 | C11: =C4 -> 84861000 | D11: 0 | E11: 0 | F11: 0 | G11: =C4 -> 84861000
B12: 1 | C12: =G11 -> 84861000 | D12: =IF(1<=C6,C7,0) -> 27136667 | E12: =IF(1<=C6,C12*C5,0) -> 15274980 | F12: =IF(1<=C6,D12-E12,0) -> 11861687 | G12: =MAX(0,C12-F12) -> 72999313
B13: 2 | C13: =G12 -> 72999313 | D13: =IF(2<=C6,C7,0) -> 27136667 | E13: =IF(2<=C6,C13*C5,0) -> 13139876 | F13: =IF(2<=C6,D13-E13,0) -> 13996791 | G13: =MAX(0,C13-F13) -> 59002521
B14: 3 | C14: =G13 -> 59002521 | D14: =IF(3<=C6,C7,0) -> 27136667 | E14: =IF(3<=C6,C14*C5,0) -> 10620454 | F14: =IF(3<=C6,D14-E14,0) -> 16516214 | G14: =MAX(0,C14-F14) -> 42486308
B15: 4 | C15: =G14 -> 42486308 | D15: =IF(4<=C6,C7,0) -> 27136667 | E15: =IF(4<=C6,C15*C5,0) -> 7647535.4 | F15: =IF(4<=C6,D15-E15,0) -> 19489132 | G15: =MAX(0,C15-F15) -> 22997176
B16: 5 | C16: =G15 -> 22997176 | D16: =IF(5<=C6,C7,0) -> 27136667 | E16: =IF(5<=C6,C16*C5,0) -> 4139491.6 | F16: =IF(5<=C6,D16-E16,0) -> 22997176 | G16: =MAX(0,C16-F16) -> 0
B17: 6 | C17: =G16 -> 0 | D17: =IF(6<=C6,C7,0) -> 0 | E17: =IF(6<=C6,C17*C5,0) -> 0 | F17: =IF(6<=C6,D17-E17,0) -> 0 | G17: =MAX(0,C17-F17) -> 0
B18: 7 | C18: =G17 -> 0 | D18: =IF(7<=C6,C7,0) -> 0 | E18: =IF(7<=C6,C18*C5,0) -> 0 | F18: =IF(7<=C6,D18-E18,0) -> 0 | G18: =MAX(0,C18-F18) -> 0
B19: 8 | C19: =G18 -> 0 | D19: =IF(8<=C6,C7,0) -> 0 | E19: =IF(8<=C6,C19*C5,0) -> 0 | F19: =IF(8<=C6,D19-E19,0) -> 0 | G19: =MAX(0,C19-F19) -> 0
B20: 9 | C20: =G19 -> 0 | D20: =IF(9<=C6,C7,0) -> 0 | E20: =IF(9<=C6,C20*C5,0) -> 0 | F20: =IF(9<=C6,D20-E20,0) -> 0 | G20: =MAX(0,C20-F20) -> 0
B21: 10 | C21: =G20 -> 0 | D21: =IF(10<=C6,C7,0) -> 0 | E21: =IF(10<=C6,C21*C5,0) -> 0 | F21: =IF(10<=C6,D21-E21,0) -> 0 | G21: =MAX(0,C21-F21) -> 0
B22: 11 | C22: =G21 -> 0 | D22: =IF(11<=C6,C7,0) -> 0 | E22: =IF(11<=C6,C22*C5,0) -> 0 | F22: =IF(11<=C6,D22-E22,0) -> 0 | G22: =MAX(0,C22-F22) -> 0
B23: 12 | C23: =G22 -> 0 | D23: =IF(12<=C6,C7,0) -> 0 | E23: =IF(12<=C6,C23*C5,0) -> 0 | F23: =IF(12<=C6,D23-E23,0) -> 0 | G23: =MAX(0,C23-F23) -> 0
B24: 13 | C24: =G23 -> 0 | D24: =IF(13<=C6,C7,0) -> 0 | E24: =IF(13<=C6,C24*C5,0) -> 0 | F24: =IF(13<=C6,D24-E24,0) -> 0 | G24: =MAX(0,C24-F24) -> 0
B25: 14 | C25: =G24 -> 0 | D25: =IF(14<=C6,C7,0) -> 0 | E25: =IF(14<=C6,C25*C5,0) -> 0 | F25: =IF(14<=C6,D25-E25,0) -> 0 | G25: =MAX(0,C25-F25) -> 0
B26: 15 | C26: =G25 -> 0 | D26: =IF(15<=C6,C7,0) -> 0 | E26: =IF(15<=C6,C26*C5,0) -> 0 | F26: =IF(15<=C6,D26-E26,0) -> 0 | G26: =MAX(0,C26-F26) -> 0
B27: 16 | C27: =G26 -> 0 | D27: =IF(16<=C6,C7,0) -> 0 | E27: =IF(16<=C6,C27*C5,0) -> 0 | F27: =IF(16<=C6,D27-E27,0) -> 0 | G27: =MAX(0,C27-F27) -> 0
B28: 17 | C28: =G27 -> 0 | D28: =IF(17<=C6,C7,0) -> 0 | E28: =IF(17<=C6,C28*C5,0) -> 0 | F28: =IF(17<=C6,D28-E28,0) -> 0 | G28: =MAX(0,C28-F28) -> 0
B29: 18 | C29: =G28 -> 0 | D29: =IF(18<=C6,C7,0) -> 0 | E29: =IF(18<=C6,C29*C5,0) -> 0 | F29: =IF(18<=C6,D29-E29,0) -> 0 | G29: =MAX(0,C29-F29) -> 0
B30: 19 | C30: =G29 -> 0 | D30: =IF(19<=C6,C7,0) -> 0 | E30: =IF(19<=C6,C30*C5,0) -> 0 | F30: =IF(19<=C6,D30-E30,0) -> 0 | G30: =MAX(0,C30-F30) -> 0
B31: 20 | C31: =G30 -> 0 | D31: =IF(20<=C6,C7,0) -> 0 | E31: =IF(20<=C6,C31*C5,0) -> 0 | F31: =IF(20<=C6,D31-E31,0) -> 0 | G31: =MAX(0,C31-F31) -> 0
B32: 21 | C32: =G31 -> 0 | D32: =IF(21<=C6,C7,0) -> 0 | E32: =IF(21<=C6,C32*C5,0) -> 0 | F32: =IF(21<=C6,D32-E32,0) -> 0 | G32: =MAX(0,C32-F32) -> 0
B33: 22 | C33: =G32 -> 0 | D33: =IF(22<=C6,C7,0) -> 0 | E33: =IF(22<=C6,C33*C5,0) -> 0 | F33: =IF(22<=C6,D33-E33,0) -> 0 | G33: =MAX(0,C33-F33) -> 0
B34: 23 | C34: =G33 -> 0 | D34: =IF(23<=C6,C7,0) -> 0 | E34: =IF(23<=C6,C34*C5,0) -> 0 | F34: =IF(23<=C6,D34-E34,0) -> 0 | G34: =MAX(0,C34-F34) -> 0
B35: 24 | C35: =G34 -> 0 | D35: =IF(24<=C6,C7,0) -> 0 | E35: =IF(24<=C6,C35*C5,0) -> 0 | F35: =IF(24<=C6,D35-E35,0) -> 0 | G35: =MAX(0,C35-F35) -> 0
B36: 25 | C36: =G35 -> 0 | D36: =IF(25<=C6,C7,0) -> 0 | E36: =IF(25<=C6,C36*C5,0) -> 0 | F36: =IF(25<=C6,D36-E36,0) -> 0 | G36: =MAX(0,C36-F36) -> 0
B37: TOTALES | D37: =SUM(D12:D36) -> 1.3568334e+08 | E37: =SUM(E12:E36) -> 50822337 | F37: =SUM(F12:F36) -> 84861000

Sheet 6_RESUMEN
B1: ☀ RESUMEN EJECUTIVO — PROYECTO FOTOVOLTAICO ON-GRID
B2: DATOS DEL PROYECTO
B3: Nombre | C3: ='1_ENTRADA'!C5 -> Proyecto Fotovoltaico On-Grid
B4: Cliente | C4: ='1_ENTRADA'!C6 -> Suegra
B5: Ubicación | C5: ='1_ENTRADA'!C7 -> Riohacha, La Guajira
B6: Operador de Red | C6: ='1_ENTRADA'!C8 -> AIR-E
B8: PARÁMETROS TÉCNICOS
B9: Potencia pico instalada | C9: ='2_CALC_KWH'!C6&" kWp" -> 12.2 kWp
B10: Energía generada / mes | C10: ='2_CALC_KWH'!C13&" kWh/mes" -> 1647 kWh/mes
B11: Consumo de la red / mes | C11: ='1_ENTRADA'!C20&" kWh/mes" -> 3700 kWh/mes
B12: Cobertura solar | C12: =TEXT('2_CALC_KWH'!C15,"0.0%") -> 44.5%
B13: Ahorro mensual año base | C13: =TEXT('2_CALC_KWH'!C25,"#,##0")&" COP/mes" -> 1,467,477 COP/mes
B15: RESULTADOS FINANCIEROS
B16: Inversión total CAPEX | C16: ='1_ENTRADA'!E47 -> 121230000
B17: Beneficio Ley 1715 | C17: ='1_ENTRADA'!E48 -> 60615000
B18: Inversión neta efectiva | C18: ='1_ENTRADA'!E49 -> 60615000
B19: VPN del proyecto | C19: ='4_INDICADORES'!C4 -> 45750253
B20: TIR del proyecto | C20: ='4_INDICADORES'!C5 -> 0.31459049
B21: Relación Beneficio/Costo | C21: ='4_INDICADORES'!C8 -> 1.4912969
B22: ROI total | C22: ='4_INDICADORES'!C9 -> 0.75961007
B23: Payback simple (años) | C23: ='4_INDICADORES'!C10 -> 3.1188911
B24: Payback descontado (años) | C24: ='4_INDICADORES'!C11 -> 3.9425865
B25: WACC | C25: ='4_INDICADORES'!C12 -> 0.12042
B27: DECISIÓN FINAL
B28: ='4_INDICADORES'!D7 -> Criterio de decisión principal
